Workbook

Sheet Estimate
A2: Ulta Beauty Fresno DC New RTUs R6 | C2: Date: 11/11/2025
A3: The Alleato Group . 8383 Craig Street #150 . Indianapolis, IN . 46250
A5: Contact | B5: Brandon Clymer | C5: bclymer@alleatogroup.com | D5: 317.760.0088
A6: Contact | B6: AJ Taylor | C6: ataylor@alleatogroup.com | D6: 317.363.3396
A7: Project: | B7: =A2 -> Ulta Beauty Fresno DC New RTUs R6
A8: Location: | B8: 850 East Central Avenue, Fresno, CA 93725
A10: Division 01 General Conditions
A11: Total | B11: ='General Conditions'!C27 -> 163252
A12: Division 02 Existing Conditions
B13: =QuantityTakeoff!Y23 -> 0 | C13: From Qty Sheet
B14: 0
A15: Total | B15: =SUBTOTAL(9,B13:B14) -> 0
A16: Division 03 Concrete
B17: =QuantityTakeoff!Y26 -> 0 | C17: From Qty Sheet
B18: 0
A19: Total | B19: =SUBTOTAL(9,B17:B18) -> 0
A20: Division 03.1 Precast
A21: Precast | C21: ATMI
A23: Total | B23: =SUBTOTAL(9,B21:B22) -> 0
A24: Division 04 Masonry
A25: Masonry | B25: =QuantityTakeoff!Y33 -> 0 | C25: From Qty Sheet
B26: 0
A27: Total | B27: =SUBTOTAL(9,B25:B26) -> 0
A28: Division 05 Metals
B29: =QuantityTakeoff!Y36 -> 247500 | C29: From Qty Sheet
B30: 0
B31: 0
A32: Total | B32: =SUBTOTAL(9,B29:B30) -> 247500
A33: Division 06 Wood Plastics Composits
B34: =QuantityTakeoff!Y41 -> 0 | C34: From Qty Sheet
B35: 0
A36: Total | B36: =SUBTOTAL(9,B34:B35) -> 0
A37: Division 07 Thermal and Moisture Protection
B38: =QuantityTakeoff!Y49 -> 72000 | C38: From Qty Sheet
B39: 0
B40: 0
B41: 0
A42: Total | B42: =SUBTOTAL(9,B38:B41) -> 72000
A43: Division 08 Openings
B44: =QuantityTakeoff!Y60 -> 0
...

Sheet General Conditions
B1: Project Duration | C1: 3 | D1: Months | E1: 12 | F1: Weeks
A3: General Conditions | E3: Quantity | F3: Unit | G3: Rate
A4: 3128 | B4: Project Manager | C4: =E4*G4 -> 45552 | E4: 12 | F4: Weeks | G4: 3796
A5: 3144 | B5: Superintendent | C5: =E5*G5 -> 40500 | E5: 12 | F5: Weeks | G5: 3375
A6: 3129 | B6: PM Fuel | C6: =E6*G6 -> 1200 | E6: 12 | F6: Weeks | G6: 100
A7: 3130 | B7: PM Truck | C7: =E7*G7 -> 3300 | E7: 6 | F7: Months | G7: 550
A8: 3245 | B8: Office Supplies | C8: =E8*G8 -> 450 | E8: 3 | F8: Months | G8: 150
A9: 3247 | B9: Printing & Copying | C9: =E9*G9 -> 2250 | E9: 3 | F9: LS | G9: 750
A10: 3329 | B10: Leed Documentation | C10: =E10*G10 -> 0 | E10: 0 | F10: LS
A11: 4126 | B11: Permit Requirements | C11: =E11*G11 -> 15000 | E11: 1 | F11: LS | G11: 15000
A12: 4523 | B12: Testing & Inspections | C12: =E12*G12 -> 3500 | E12: 1 | F12: LS | G12: 3500
A13: 5113 | B13: Temporary Electric | C13: =E13*G13 -> 0 | E13: 0 | F13: Months | G13: 1000
A14: 5216 | B14: First Aid/Safety Supplies | C14: =E14*G14 -> 0 | E14: 0 | F14: Months | G14: 75
A15: 5213 | B15: Field Office | C15: =E15*G15 -> 0 | E15: 0 | F15: Months | G15: 650
A16: 5217 | B16: Safety Inspections | C16: =E16*G16 -> 0 | E16: 0 | F16: Months | G16: 150
A17: 5219 | B17: Temp Toilets | C17: =E17*G17 -> 0 | E17: 0 | F17: Months | G17: 350
A18: 6113 | B18: Software Licensing | C18: =E18*G18 -> 1500 | E18: 1 | F18: LS | G18: 1500
A19: 6500 | B19: Travel & Entertaintment | C19: =E19*G19 -> 36000 | E19: 3 | F19: Months | G19: 12000
A20: 7333 | B20: Misc Small Tools | C20: =E20*G20 -> 0 | E20: 0 | F20: Months | G20: 500
A21: 7336 | B21: Equipment Rental | C21: =E21*G21 -> 3750 | E21: 5 | F21: Months | G21: 750
A22: 7413 | B22: Progress Cleaning | C22: =E22*G22 -> 3250 | E22: 5 | F22: Months | G22: 650
A23: 7419 | B23: Dumpsters | C23: =E23*G23 -> 4500 | E23: 6 | F23: EA | G23: 750
B24: Temp Fencing | C24: =E24*G24 -> 0 | E24: 0 | F24: lf | G24: 10
A25: 7423 | B25: Final Cleaning | C25: =E25*G25 -> 2500 | E25: 5000 | F25: SF | G25: 0.5
A27: Total | C27: =ROUNDUP(SUM(C4:C25),0) -> 163252

Sheet QuantityTakeoff
A2: Client: | C2: Ulta Beauty | F2: Job Name: | H2: Ulta Fresno New RTUs R1 | M2: Estimate Number:
A3: Location: | C3: Fresno, California | F3: Estimate Date: | H3: 45501
A4: Estimator: | C4: AJ Taylor | F4: Revision Date: | H4: 45875
D6: Dimensions | J6: Material | M6: Labor | Q6: Equipment (incl fuel) | U6: Subcontract
A7: Line | B7: Division | C7: Description | D7: Length | E7: Width | F7: Depth | G7: No. of Ea. | H7: Quantity | I7: Unit | J7: Unit Price | K7: Cost | L7: Crew | M7: Hrs | N7: MH | O7: Rate | P7: Cost | Q7: Duration | R7: Unit | S7: Rate | T7: Cost | U7: Unit Price | V7: Cost | W7: Total Cost | X7: Comments
A8: 1 | B8: 00 Design | K8: =J8*H8 -> 0 | N8: =ROUND(L8*M8*H8,0) -> 0 | P8: =O8*N8 -> 0 | T8: =S8*Q8 -> 0 | V8: =H8*U8 -> 0 | W8: =V8+T8+P8+K8 -> 0 | Y8: =SUM(W8:W16) -> 0
A9: =A8+1 -> 2 | C9: Alleato Coordination | H9: 0 | I9: lot | K9: =J9*H9 -> 0 | N9: =ROUND(L9*M9*H9,0) -> 0 | P9: =O9*N9 -> 0 | T9: =S9*Q9 -> 0 | U9: 7000 | V9: =H9*U9 -> 0 | W9: =V9+T9+P9+K9 -> 0
A10: =A9+1 -> 3 | C10: Boundary Survey | H10: 0 | I10: lot | K10: =J10*H10 -> 0 | N10: =ROUND(L10*M10*H10,0) -> 0 | P10: =O10*N10 -> 0 | T10: =S10*Q10 -> 0 | U10: 0 | V10: =H10*U10 -> 0 | W10: =V10+T10+P10+K10 -> 0
A11: =A10+1 -> 4 | C11: Topographic Survey | H11: 0 | I11: lot | K11: =J11*H11 -> 0 | N11: =ROUND(L11*M11*H11,0) -> 0 | P11: =O11*N11 -> 0 | T11: =S11*Q11 -> 0 | U11: 0 | V11: =H11*U11 -> 0 | W11: =V11+T11+P11+K11 -> 0
A12: =A11+1 -> 5 | C12: Geotechnical Survey | H12: 0 | I12: lot | K12: =J12*H12 -> 0 | N12: =ROUND(L12*M12*H12,0) -> 0 | P12: =O12*N12 -> 0 | T12: =S12*Q12 -> 0 | U12: 0 | V12: =H12*U12 -> 0 | W12: =V12+T12+P12+K12 -> 0
A13: =A12+1 -> 6 | C13: Civil Design | H13: 0 | I13: lot | K13: =J13*H13 -> 0 | N13: =ROUND(L13*M13*H13,0) -> 0 | P13: =O13*N13 -> 0 | T13: =S13*Q13 -> 0 | U13: 0 | V13: =H13*U13 -> 0 | W13: =V13+T13+P13+K13 -> 0
A14: =A13+1 -> 7 | C14: Architectural Design | H14: 0 | I14: lot | K14: =J14*H14 -> 0 | N14: =ROUND(L14*M14*H14,0) -> 0 | P14: =O14*N14 -> 0 | T14: =S14*Q14 -> 0 | U14: 5000 | V14: =H14*U14 -> 0 | W14: =V14+T14+P14+K14 -> 0
A15: =A14+1 -> 8 | C15: Structural | H15: 0 | I15: lot | K15: =J15*H15 -> 0 | N15: =ROUND(L15*M15*H15,0) -> 0 | P15: =O15*N15 -> 0 | T15: =S15*Q15 -> 0 | U15: 5000 | V15: =H15*U15 -> 0 | W15: =V15+T15+P15+K15 -> 0
A16: =A15+1 -> 9 | C16: MEP Design | H16: 0 | I16: lot | K16: =J16*H16 -> 0 | N16: =ROUND(L16*M16*H16,0) -> 0 | P16: =O16*N16 -> 0 | T16: =S16*Q16 -> 0 | U16: 1000 | V16: =H16*U16 -> 0 | W16: =V16+T16+P16+K16 -> 0
A17: =A16+1 -> 10 | B17: 01 General Conditions | K17: =J17*H17 -> 0 | N17: =ROUND(L17*M17*H17,0) -> 0 | P17: =O17*N17 -> 0 | T17: =S17*Q17 -> 0 | V17: =H17*U17 -> 0 | W17: =V17+T17+P17+K17 -> 0 | Y17: =SUM(W17:W22) -> 0
A18: =A17+1 -> 11 | C18: Application Fees | H18: 0 | I18: lot | K18: =J18*H18 -> 0 | N18: =ROUND(L18*M18*H18,0) -> 0 | P18: =O18*N18 -> 0 | T18: =S18*Q18 -> 0 | U18: 4000 | V18: =H18*U18 -> 0 | W18: =V18+T18+P18+K18 -> 0
A19: =A18+1 -> 12 | C19: State Release ($150 + $.05 x floor sq footage) | I19: lot | K19: =J19*H19 -> 0 | N19: =ROUND(L19*M19*H19,0) -> 0 | P19: =O19*N19 -> 0 | T19: =S19*Q19 -> 0 | U19: 0 | V19: =H19*U19 -> 0 | W19: =V19+T19+P19+K19 -> 0
A20: =A19+1 -> 13 | C20: Local Permits | H20: 0 | I20: lot | K20: =J20*H20 -> 0 | N20: =ROUND(L20*M20*H20,0) -> 0 | P20: =O20*N20 -> 0 | T20: =S20*Q20 -> 0 | U20: 4000 | V20: =H20*U20 -> 0 | W20: =V20+T20+P20+K20 -> 0
A21: =A20+1 -> 14 | C21: Local Planning | H21: 0 | I21: lot | K21: =J21*H21 -> 0 | N21: =ROUND(L21*M21*H21,0) -> 0 | P21: =O21*N21 -> 0 | T21: =S21*Q21 -> 0 | U21: 4000 | V21: =H21*U21 -> 0 | W21: =V21+T21+P21+K21 -> 0
A22: =A21+1 -> 15 | K22: =J22*H22 -> 0 | N22: =ROUND(L22*M22*H22,0) -> 0 | P22: =O22*N22 -> 0 | T22: =S22*Q22 -> 0 | V22: =H22*U22 -> 0 | W22: =V22+T22+P22+K22 -> 0
A23: =A22+1 -> 16 | B23: 02 Existing Conditions | K23: =J23*H23 -> 0 | N23: =ROUND(L23*M23*H23,0) -> 0 | P23: =O23*N23 -> 0 | T23: =S23*Q23 -> 0 | V23: =H23*U23 -> 0 | W23: =V23+T23+P23+K23 -> 0 | Y23: =SUM(W23:W25) -> 0
A24: =A23+1 -> 17 | H24: 0 | I24: lot | K24: =J24*H24 -> 0 | L24: 1 | M24: 4 | N24: =ROUND(L24*M24*H24,0) -> 0 | O24: 50 | P24: =O24*N24 -> 0 | T24: =S24*Q24 -> 0 | U24: 0 | V24: =H24*U24 -> 0 | W24: =V24+T24+P24+K24 -> 0
A25: =A24+1 -> 18 | H25: 0 | I25: lot | K25: =J25*H25 -> 0 | N25: =ROUND(L25*M25*H25,0) -> 0 | P25: =O25*N25 -> 0 | T25: =S25*Q25 -> 0 | U25: 0 | V25: =H25*U25 -> 0 | W25: =V25+T25+P25+K25 -> 0 | X25: SWAG
A26: =A25+1 -> 19 | B26: 03 Concrete | K26: =J26*H26 -> 0 | N26: =ROUND(L26*M26*H26,0) -> 0 | P26: =O26*N26 -> 0 | T26: =S26*Q26 -> 0 | V26: =H26*U26 -> 0 | W26: =V26+T26+P26+K26 -> 0 | Y26: =SUM(W26:W32) -> 0
A27: =A26+1 -> 20 | C27: Transformer Pads | I27: EA | K27: =J27*H27 -> 0 | N27: =ROUND(L27*M27*H27,0) -> 0 | P27: =O27*N27 -> 0 | T27: =S27*Q27 -> 0 | U27: 2500 | V27: =H27*U27 -> 0 | W27: =V27+T27+P27+K27 -> 0 | X27: Included in Mid South
A28: =A27+1 -> 21 | C28: Generator Pads | I28: EA | K28: =J28*H28 -> 0 | N28: =ROUND(L28*M28*H28,0) -> 0 | P28: =O28*N28 -> 0 | T28: =S28*Q28 -> 0 | U28: 5000 | V28: =H28*U28 -> 0 | W28: =V28+T28+P28+K28 -> 0 | X28: Included in Mid South | Y28: internal cont. | Z28: 18300
A29: =A28+1 -> 22 | C29: Bollard Concrete | I29: EA | K29: =J29*H29 -> 0 | N29: =ROUND(L29*M29*H29,0) -> 0 | P29: =O29*N29 -> 0 | T29: =S29*Q29 -> 0 | U29: 200 | V29: =H29*U29 -> 0 | W29: =V29+T29+P29+K29 -> 0 | X29: Included in Mid South
A30: =A29+1 -> 23 | C30: Rebar | I30: LS | K30: =J30*H30 -> 0 | N30: =ROUND(L30*M30*H30,0) -> 0 | P30: =O30*N30 -> 0 | T30: =S30*Q30 -> 0 | U30: 1050 | V30: =H30*U30 -> 0 | W30: =V30+T30+P30+K30 -> 0 | X30: Included in Mid South
A31: =A30+1 -> 24 | C31: Concrete Subcontractor Include stoop at door | I31: lot | K31: =J31*H31 -> 0 | N31: =ROUND(L31*M31*H31,0) -> 0 | P31: =O31*N31 -> 0 | T31: =S31*Q31 -> 0 | U31: 20000 | V31: =H31*U31 -> 0 | W31: =V31+T31+P31+K31 -> 0 | X31: Plug Number
A32: =A31+1 -> 25 | H32: 0 | I32: lot | K32: =J32*H32 -> 0 | N32: =ROUND(L32*M32*H32,0) -> 0 | P32: =O32*N32 -> 0 | T32: =S32*Q32 -> 0 | U32: 0 | V32: =H32*U32 -> 0 | W32: =V32+T32+P32+K32 -> 0
A33: =A32+1 -> 26 | B33: 04 Masonry | K33: =J33*H33 -> 0 | N33: =ROUND(L33*M33*H33,0) -> 0 | P33: =O33*N33 -> 0 | T33: =S33*Q33 -> 0 | V33: =H33*U33 -> 0 | W33: =V33+T33+P33+K33 -> 0 | Y33: =SUM(W33:W35) -> 0
A34: =A33+1 -> 27 | I34: sf | K34: =J34*H34 -> 0 | N34: =ROUND(L34*M34*H34,0) -> 0 | P34: =O34*N34 -> 0 | T34: =S34*Q34 -> 0 | V34: =H34*U34 -> 0 | W34: =V34+T34+P34+K34 -> 0
A35: =A34+1 -> 28 | I35: lf | K35: =J35*H35 -> 0 | N35: =ROUND(L35*M35*H35,0) -> 0 | P35: =O35*N35 -> 0 | T35: =S35*Q35 -> 0 | V35: =H35*U35 -> 0 | W35: =V35+T35+P35+K35 -> 0
A36: =A35+1 -> 29 | B36: 05 Metals | K36: =J36*H36 -> 0 | N36: =ROUND(L36*M36*H36,0) -> 0 | P36: =O36*N36 -> 0 | T36: =S36*Q36 -> 0 | V36: =H36*U36 -> 0 | W36: =V36+T36+P36+K36 -> 0 | Y36: =SUM(W36:W40) -> 247500
A37: =A36+1 -> 30 | K37: =J37*H37 -> 0 | N37: =ROUND(L37*M37*H37,0) -> 0 | P37: =O37*N37 -> 0 | T37: =S37*Q37 -> 0 | V37: =H37*U37 -> 0 | W37: =V37+T37+P37+K37 -> 0
A38: =A37+1 -> 31 | C38: Reinforce Joists 8 AANON Units reuse spaces | H38: 45 | I38: ea | K38: =J38*H38 -> 0 | N38: =ROUND(L38*M38*H38,0) -> 0 | P38: =O38*N38 -> 0 | T38: =S38*Q38 -> 0 | U38: 4500 | V38: =H38*U38 -> 202500 | W38: =V38+T38+P38+K38 -> 202500
A39: =A38+1 -> 32 | C39: internal cont. | H39: 1 | I39: lot | K39: =J39*H39 -> 0 | N39: =ROUND(L39*M39*H39,0) -> 0 | P39: =O39*N39 -> 0 | T39: =S39*Q39 -> 0 | U39: 25000 | V39: =H39*U39 -> 25000 | W39: =V39+T39+P39+K39 -> 25000 | X39: Allowance
A40: =A39+1 -> 33 | C40: Design | H40: 1 | I40: lot | K40: =J40*H40 -> 0 | N40: =ROUND(L40*M40*H40,0) -> 0 | P40: =O40*N40 -> 0 | T40: =S40*Q40 -> 0 | U40: 20000 | V40: =H40*U40 -> 20000 | W40: =V40+T40+P40+K40 -> 20000
A41: =A40+1 -> 34 | B41: 06 Wood Plastics Composits | K41: =J41*H41 -> 0 | N41: =ROUND(L41*M41*H41,0) -> 0 | P41: =O41*N41 -> 0 | T41: =S41*Q41 -> 0 | V41: =H41*U41 -> 0 | W41: =V41+T41+P41+K41 -> 0 | Y41: =SUM(W41:W48) -> 0
A42: =A41+1 -> 35 | C42: Hardi Board | H42: 0 | I42: lot | K42: =J42*H42 -> 0 | N42: =ROUND(L42*M42*H42,0) -> 0 | P42: =O42*N42 -> 0 | T42: =S42*Q42 -> 0 | U42: 0 | V42: =H42*U42 -> 0 | W42: =V42+T42+P42+K42 -> 0
...
