Workbook

Sheet Estimate
A3: The Alleato Group . 8383 Craig Street #150 . Indianapolis, IN . 46250
A5: Contact | B5: Brandon Clymer | C5: bclymer@alleatogroup.com | D5: 317.760.0088
A6: Contact | B6: AJ Taylor | C6: ataylor@alleatogroup.com | D6: 317.363.3396
A8: Project:
A9: Location:
A11: Division 01 General Conditions
A12: Total | B12: ='General Conditions'!C76 -> 0
A13: Division 02 Existing Conditions
B14: =QuantityTakeoff!Y25 -> 0 | C14: From Qty Sheet
B15: 0
A16: Total | B16: =SUBTOTAL(9,B14:B15) -> 0
A17: Division 03 Concrete
B18: =QuantityTakeoff!Y41 -> 0 | C18: From Qty Sheet
B19: 0
A20: Total | B20: =SUBTOTAL(9,B18:B19) -> 0
A21: Division 03.1 Precast
A22: Precast | C22: ATMI
A24: Total | B24: =SUBTOTAL(9,B22:B23) -> 0
A25: Division 04 Masonry
A26: Masonry | B26: =QuantityTakeoff!Y53 -> 0 | C26: From Qty Sheet
B27: 0
A28: Total | B28: =SUBTOTAL(9,B26:B27) -> 0
A29: Division 05 Metals
A30: bollards | B30: =QuantityTakeoff!Y60 -> 0 | C30: From Qty Sheet
B31: 0
B32: 0
A33: Total | B33: =SUBTOTAL(9,B30:B31) -> 0
A34: Division 06 Wood Plastics Composits
B35: =QuantityTakeoff!Y71 -> 0 | C35: From Qty Sheet
B36: 0
A37: Total | B37: =SUBTOTAL(9,B35:B36) -> 0
A38: Division 07 Thermal and Moisture Protection
B39: =QuantityTakeoff!Y87 -> 0 | C39: From Qty Sheet
B40: 0
B41: 0
B42: 0
A43: Total | B43: =SUBTOTAL(9,B39:B42) -> 0
A44: Division 08 Openings
B45: =QuantityTakeoff!Y98 -> 0 | C45: From Qty Sheet
B46: 0
...

Sheet General Conditions
B1: Project Duration | D1: Months | F1: Weeks
A3: General Conditions | E3: Quantity | F3: Unit | G3: Rate
A4: 01-3120 | B4: Vice President | C4: =E4*G4 -> 0 | E4: =G1 -> 0 | F4: Weeks | G4: 3115
A5: 01-3126 | B5: Pre-construction | C5: =E5*G5 -> 0 | E5: =G1 -> 0 | F5: Weeks | G5: 2596
A6: 01-3127 | B6: Sr. Project Manager | C6: =E6*G6 -> 0 | E6: =G1 -> 0 | F6: Weeks | G6: 2800
A7: 01-3128 | B7: Project Manager | C7: =E7*G7 -> 0 | E7: =G1 -> 0 | F7: Weeks | G7: 2100
A8: 01-3129 | B8: Assistant Project Manager (APM) | C8: =E8*G8 -> 0 | E8: =G1 -> 0 | F8: Weeks | G8: 1500
A9: 01-3130 | B9: Project Engineer | C9: =E9*G9 -> 0 | E9: =G1 -> 0 | F9: Weeks | G9: 1100
A10: 01-3131 | B10: Field Engineer | C10: =E10*G10 -> 0 | E10: =G1 -> 0 | F10: Weeks | G10: 1100
A11: 01-3132 | B11: Intern | C11: =E11*G11 -> 0 | E11: =G1 -> 0 | F11: Weeks | G11: 850
A12: 01-3142 | B12: General Superintendent | C12: =E12*G12 -> 0 | E12: =G1 -> 0 | F12: Weeks | G12: 2800
A13: 01-3143 | B13: Sr. Superintendent | C13: =E13*G13 -> 0 | E13: =G1 -> 0 | F13: Weeks | G13: 2500
A14: 01-3144 | B14: Superintendent | C14: =E14*G14 -> 0 | E14: =G1 -> 0 | F14: Weeks | G14: 2100
A15: 01-3145 | B15: Assistant Superintendent | C15: =E15*G15 -> 0 | E15: =G1 -> 0 | F15: Weeks | G15: 650
A16: 01-3223 | B16: Construction Layout | C16: =E16*G16 -> 0 | E16: =E1 -> 0 | F16: Months | G16: 150
A17: 01-3236 | B17: Aerial & Periodic Drones | C17: =E17*G17 -> 0 | E17: =E1 -> 0 | F17: Months | G17: 350
A18: 01-3238 | B18: Jobsite Security | C18: =E18*G18 -> 0 | E18: 1 | F18: LS
A19: 01-3245 | B19: Office Supplies | C19: =E19*G19 -> 0 | E19: =E1 -> 0 | F19: Months | G19: 500
A20: 01-3247 | B20: Printing & Copying | C20: =E20*G20 -> 0 | E20: =E1 -> 0 | F20: Months | G20: 500
A21: 01-3249 | B21: Postage & Courier | C21: =E21*G21 -> 0 | E21: =E1 -> 0 | F21: Months | G21: 750
A22: 01-3329 | B22: LEED Documentation | C22: =E22*G22 -> 0 | E22: =E1 -> 0 | F22: Months | G22: 650
A23: 01-3514 | B23: Legal Fees | C23: =E23*G23 -> 0 | F23: LS | G23: 0
A24: 01-4123 | B24: Fees | C24: =E24*G24 -> 0 | F24: SF | G24: 1.25
A25: 01-4124 | B25: Sanitary Fees | C25: =E25*G25 -> 0 | F25: SF | G25: 1.25
A26: 01-4126 | B26: Permit Requirements | C26: =E26*G26 -> 0 | E26: 1 | F26: LS | G26: 0
A27: 01-4523 | B27: Testing and Inspections | C27: =E27*G27 -> 0 | E27: 1 | F27: LS | G27: 0
A28: 01-4533 | B28: Municipality Inspections | C28: =E28*G28 -> 0 | F28: EA | G28: 0
A29: 01-4613 | B29: Winter Conditions | C29: =E29*G29 -> 0 | E29: 1 | F29: LS | G29: 0
A30: 01-5113 | B30: Temporary Electric | C30: =E30*G30 -> 0 | E30: =E1 -> 0 | F30: Months | G30: 300
A31: 01-5116 | B31: Temporary Fire Protection | C31: =E31*G31 -> 0 | E31: =E1 -> 0 | F31: Months
A32: 01-5119 | B32: Temporary Fuel | C32: =E32*G32 -> 0 | E32: =E1 -> 0 | F32: Weeks | G32: 100
A33: 01-5123 | B33: Temporary HVAC | C33: =E33*G33 -> 0 | E33: =E1 -> 0 | F33: Months
A34: 01-5126 | B34: Temporary Lighting | C34: =E34*G34 -> 0 | E34: 1 | F34: LS
A35: 01-5129 | B35: Temporary Gas | C35: =E35*G35 -> 0 | E35: =E1 -> 0 | F35: Months | G35: 0
A36: 01-5133 | B36: Temporary Internet/Telecomm | C36: =E36*G36 -> 0 | E36: =E1 -> 0 | F36: Months | G36: 100
A37: 01-5136 | B37: Temporary Water | C37: =E37*G37 -> 0 | E37: =E1 -> 0 | F37: Months | G37: 0
A38: 01-5213 | B38: Field Offices | C38: =E38*G38 -> 0 | E38: =E1 -> 0 | F38: Months | G38: 0
A39: 01-5214 | B39: Temporary Storage | C39: =E39*G39 -> 0 | E39: =E1 -> 0 | F39: Months | G39: 0
A40: 01-5216 | B40: First Aid / Safety Supplies | C40: =E40*G40 -> 0 | E40: 0 | F40: LS | G40: 350
A41: 01-5217 | B41: Safety Inspections | C41: =E41*G41 -> 0 | E41: =E1 -> 0 | F41: Months | G41: 450
...

Sheet QuantityTakeoff
A2: Client: | F2: Job Name: | M2: Estimate Number:
A3: Location: | F3: Estimate Date:
A4: Estimator: | F4: Revision Date:
D6: Dimensions | J6: Material | M6: Labor | Q6: Equipment (incl fuel) | U6: Subcontract
A7: Line | B7: Division | C7: Description | D7: Length | E7: Width | F7: Depth | G7: No. of Ea. | H7: Quantity | I7: Unit | J7: Unit Price | K7: Cost | L7: Crew | M7: Hrs | N7: MH | O7: Rate | P7: Cost | Q7: Duration | R7: Unit | S7: Rate | T7: Cost | U7: Unit Price | V7: Cost | W7: Total Cost | X7: Comments
A8: 1 | B8: 00 Design | K8: =J8*H8 -> 0 | N8: =ROUND(L8*M8*H8,0) -> 0 | P8: =O8*N8 -> 0 | T8: =S8*Q8 -> 0 | V8: =H8*U8 -> 0 | W8: =V8+T8+P8+K8 -> 0 | Y8: =SUM(W8:W18) -> 0
A9: =A8+1 -> 2 | C9: Alleato Coordination | I9: lot | K9: =J9*H9 -> 0 | N9: =ROUND(L9*M9*H9,0) -> 0 | P9: =O9*N9 -> 0 | T9: =S9*Q9 -> 0 | V9: =H9*U9 -> 0 | W9: =V9+T9+P9+K9 -> 0
A10: =A9+1 -> 3 | C10: Boundary Survey | I10: lot | K10: =J10*H10 -> 0 | N10: =ROUND(L10*M10*H10,0) -> 0 | P10: =O10*N10 -> 0 | T10: =S10*Q10 -> 0 | V10: =H10*U10 -> 0 | W10: =V10+T10+P10+K10 -> 0
A11: =A10+1 -> 4 | C11: Topographic Survey | I11: lot | K11: =J11*H11 -> 0 | N11: =ROUND(L11*M11*H11,0) -> 0 | P11: =O11*N11 -> 0 | T11: =S11*Q11 -> 0 | V11: =H11*U11 -> 0 | W11: =V11+T11+P11+K11 -> 0
A12: =A11+1 -> 5 | C12: Geotechnical Survey | I12: lot | K12: =J12*H12 -> 0 | N12: =ROUND(L12*M12*H12,0) -> 0 | P12: =O12*N12 -> 0 | T12: =S12*Q12 -> 0 | V12: =H12*U12 -> 0 | W12: =V12+T12+P12+K12 -> 0
A13: =A12+1 -> 6 | C13: Civil Design | I13: lot | K13: =J13*H13 -> 0 | N13: =ROUND(L13*M13*H13,0) -> 0 | P13: =O13*N13 -> 0 | T13: =S13*Q13 -> 0 | V13: =H13*U13 -> 0 | W13: =V13+T13+P13+K13 -> 0
A14: =A13+1 -> 7 | C14: Architectural Design | I14: lot | K14: =J14*H14 -> 0 | N14: =ROUND(L14*M14*H14,0) -> 0 | P14: =O14*N14 -> 0 | T14: =S14*Q14 -> 0 | V14: =H14*U14 -> 0 | W14: =V14+T14+P14+K14 -> 0
A15: =A14+1 -> 8 | C15: Structural | I15: lot | K15: =J15*H15 -> 0 | N15: =ROUND(L15*M15*H15,0) -> 0 | P15: =O15*N15 -> 0 | T15: =S15*Q15 -> 0 | V15: =H15*U15 -> 0 | W15: =V15+T15+P15+K15 -> 0
A16: =A15+1 -> 9 | C16: MEP Design | I16: lot | K16: =J16*H16 -> 0 | N16: =ROUND(L16*M16*H16,0) -> 0 | P16: =O16*N16 -> 0 | T16: =S16*Q16 -> 0 | V16: =H16*U16 -> 0 | W16: =V16+T16+P16+K16 -> 0
A17: =A16+1 -> 10 | C17: Landscape Design | I17: lot | K17: =J17*H17 -> 0 | N17: =ROUND(L17*M17*H17,0) -> 0 | P17: =O17*N17 -> 0 | T17: =S17*Q17 -> 0 | V17: =H17*U17 -> 0 | W17: =V17+T17+P17+K17 -> 0
A18: =A17+1 -> 11 | I18: lot | K18: =J18*H18 -> 0 | N18: =ROUND(L18*M18*H18,0) -> 0 | P18: =O18*N18 -> 0 | T18: =S18*Q18 -> 0 | V18: =H18*U18 -> 0 | W18: =V18+T18+P18+K18 -> 0
A19: =A18+1 -> 12 | B19: 01 General Conditions | K19: =J19*H19 -> 0 | N19: =ROUND(L19*M19*H19,0) -> 0 | P19: =O19*N19 -> 0 | T19: =S19*Q19 -> 0 | V19: =H19*U19 -> 0 | W19: =V19+T19+P19+K19 -> 0
A20: =A19+1 -> 13 | B20: 01-3120 | C20: =IFERROR(VLOOKUP(B20,'Importer Data Fields'!C2:D358,2,0),"") -> Vice President | I20: lot | K20: =J20*H20 -> 0 | N20: =ROUND(L20*M20*H20,0) -> 0 | P20: =O20*N20 -> 0 | T20: =S20*Q20 -> 0 | V20: =H20*U20 -> 0 | W20: =V20+T20+P20+K20 -> 0
A21: =A20+1 -> 14 | C21: =IFERROR(VLOOKUP(B21,'Importer Data Fields'!C3:D359,2,0),"") | I21: lot | K21: =J21*H21 -> 0 | N21: =ROUND(L21*M21*H21,0) -> 0 | P21: =O21*N21 -> 0 | T21: =S21*Q21 -> 0 | V21: =H21*U21 -> 0 | W21: =V21+T21+P21+K21 -> 0
A22: =A21+1 -> 15 | B22: 01-4126 | C22: =IFERROR(VLOOKUP(B22,'Importer Data Fields'!C4:D360,2,0),"") -> Permit Requirements | I22: lot | K22: =J22*H22 -> 0 | N22: =ROUND(L22*M22*H22,0) -> 0 | P22: =O22*N22 -> 0 | T22: =S22*Q22 -> 0 | V22: =H22*U22 -> 0 | W22: =V22+T22+P22+K22 -> 0
A23: =A22+1 -> 16 | B23: 01-4126 | C23: =IFERROR(VLOOKUP(B23,'Importer Data Fields'!C5:D361,2,0),"") -> Permit Requirements | I23: lot | K23: =J23*H23 -> 0 | N23: =ROUND(L23*M23*H23,0) -> 0 | P23: =O23*N23 -> 0 | T23: =S23*Q23 -> 0 | V23: =H23*U23 -> 0 | W23: =V23+T23+P23+K23 -> 0
A24: =A23+1 -> 17 | C24: =IFERROR(VLOOKUP(B24,'Importer Data Fields'!C6:D362,2,0),"") | K24: =J24*H24 -> 0 | N24: =ROUND(L24*M24*H24,0) -> 0 | P24: =O24*N24 -> 0 | T24: =S24*Q24 -> 0 | V24: =H24*U24 -> 0 | W24: =V24+T24+P24+K24 -> 0
A25: =A24+1 -> 18 | B25: 02 Existing Conditions | K25: =J25*H25 -> 0 | N25: =ROUND(L25*M25*H25,0) -> 0 | P25: =O25*N25 -> 0 | T25: =S25*Q25 -> 0 | V25: =H25*U25 -> 0 | W25: =V25+T25+P25+K25 -> 0 | Y25: =SUM(W25:W40) -> 0
A26: =A25+1 -> 19 | B26: 02-0150 | C26: =IFERROR(VLOOKUP(B26,'Importer Data Fields'!C:D,2,0),"") -> Maintenance & Site Remediation | I26: lot | K26: =J26*H26 -> 0 | N26: =ROUND(L26*M26*H26,0) -> 0 | P26: =O26*N26 -> 0 | T26: =S26*Q26 -> 0 | V26: =H26*U26 -> 0 | W26: =V26+T26+P26+K26 -> 0
A27: =A26+1 -> 20 | B27: 02-4116 | C27: =IFERROR(VLOOKUP(B27,'Importer Data Fields'!C:D,2,0),"") -> Structure Demolition | I27: lot | K27: =J27*H27 -> 0 | N27: =ROUND(L27*M27*H27,0) -> 0 | P27: =O27*N27 -> 0 | T27: =S27*Q27 -> 0 | V27: =H27*U27 -> 0 | W27: =V27+T27+P27+K27 -> 0
A28: =A27+1 -> 21 | B28: 02-4116 | C28: =IFERROR(VLOOKUP(B28,'Importer Data Fields'!C:D,2,0),"") -> Structure Demolition | I28: lot | K28: =J28*H28 -> 0 | N28: =ROUND(L28*M28*H28,0) -> 0 | P28: =O28*N28 -> 0 | T28: =S28*Q28 -> 0 | V28: =H28*U28 -> 0 | W28: =V28+T28+P28+K28 -> 0
A29: =A28+1 -> 22 | B29: 02-4113 | C29: =IFERROR(VLOOKUP(B29,'Importer Data Fields'!C:D,2,0),"") -> Selective Interior Demolition | I29: lf | K29: =J29*H29 -> 0 | N29: =ROUND(L29*M29*H29,0) -> 0 | P29: =O29*N29 -> 0 | T29: =S29*Q29 -> 0 | V29: =H29*U29 -> 0 | W29: =V29+T29+P29+K29 -> 0
A30: =A29+1 -> 23 | B30: 02-4113 | C30: =IFERROR(VLOOKUP(B30,'Importer Data Fields'!C:D,2,0),"") -> Selective Interior Demolition | I30: lot | K30: =J30*H30 -> 0 | N30: =ROUND(L30*M30*H30,0) -> 0 | P30: =O30*N30 -> 0 | T30: =S30*Q30 -> 0 | V30: =H30*U30 -> 0 | W30: =V30+T30+P30+K30 -> 0
A31: =A30+1 -> 24 | B31: 02-4113 | C31: =IFERROR(VLOOKUP(B31,'Importer Data Fields'!C:D,2,0),"") -> Selective Interior Demolition | I31: sf | K31: =J31*H31 -> 0 | N31: =ROUND(L31*M31*H31,0) -> 0 | P31: =O31*N31 -> 0 | T31: =S31*Q31 -> 0 | V31: =H31*U31 -> 0 | W31: =V31+T31+P31+K31 -> 0
A32: =A31+1 -> 25 | B32: 02-4116 | C32: =IFERROR(VLOOKUP(B32,'Importer Data Fields'!C:D,2,0),"") -> Structure Demolition | I32: lot | K32: =J32*H32 -> 0 | N32: =ROUND(L32*M32*H32,0) -> 0 | P32: =O32*N32 -> 0 | T32: =S32*Q32 -> 0 | V32: =H32*U32 -> 0 | W32: =V32+T32+P32+K32 -> 0
A33: =A32+1 -> 26 | B33: 02-4113 | C33: =IFERROR(VLOOKUP(B33,'Importer Data Fields'!C:D,2,0),"") -> Selective Interior Demolition | I33: lot | K33: =J33*H33 -> 0 | N33: =ROUND(L33*M33*H33,0) -> 0 | P33: =O33*N33 -> 0 | T33: =S33*Q33 -> 0 | V33: =H33*U33 -> 0 | W33: =V33+T33+P33+K33 -> 0
A34: =A33+1 -> 27 | B34: 02-2219 | C34: =IFERROR(VLOOKUP(B34,'Importer Data Fields'!C:D,2,0),"") -> Traffic Assessment | K34: =J34*H34 -> 0 | N34: =ROUND(L34*M34*H34,0) -> 0 | P34: =O34*N34 -> 0 | T34: =S34*Q34 -> 0 | V34: =H34*U34 -> 0 | W34: =V34+T34+P34+K34 -> 0
A35: =A34+1 -> 28 | B35: 02-2400 | C35: =IFERROR(VLOOKUP(B35,'Importer Data Fields'!C:D,2,0),"") -> Environmental Assessments | I35: lf | K35: =J35*H35 -> 0 | N35: =ROUND(L35*M35*H35,0) -> 0 | P35: =O35*N35 -> 0 | T35: =S35*Q35 -> 0 | V35: =H35*U35 -> 0 | W35: =V35+T35+P35+K35 -> 0
A36: =A35+1 -> 29 | B36: 02-4116 | C36: =IFERROR(VLOOKUP(B36,'Importer Data Fields'!C:D,2,0),"") -> Structure Demolition | I36: lot | K36: =J36*H36 -> 0 | N36: =ROUND(L36*M36*H36,0) -> 0 | P36: =O36*N36 -> 0 | T36: =S36*Q36 -> 0 | V36: =H36*U36 -> 0 | W36: =V36+T36+P36+K36 -> 0
A37: =A36+1 -> 30 | C37: =IFERROR(VLOOKUP(B37,'Importer Data Fields'!C:D,2,0),"") | I37: lot | K37: =J37*H37 -> 0 | N37: =ROUND(L37*M37*H37,0) -> 0 | P37: =O37*N37 -> 0 | T37: =S37*Q37 -> 0 | V37: =H37*U37 -> 0 | W37: =V37+T37+P37+K37 -> 0
A38: =A37+1 -> 31 | B38: 02-0150 | C38: =IFERROR(VLOOKUP(B38,'Importer Data Fields'!C:D,2,0),"") -> Maintenance & Site Remediation | I38: lot | K38: =J38*H38 -> 0 | N38: =ROUND(L38*M38*H38,0) -> 0 | P38: =O38*N38 -> 0 | T38: =S38*Q38 -> 0 | V38: =H38*U38 -> 0 | W38: =V38+T38+P38+K38 -> 0
A39: =A38+1 -> 32 | C39: =IFERROR(VLOOKUP(B39,'Importer Data Fields'!C:D,2,0),"") | I39: sf | K39: =J39*H39 -> 0 | N39: =ROUND(L39*M39*H39,0) -> 0 | P39: =O39*N39 -> 0 | T39: =S39*Q39 -> 0 | V39: =H39*U39 -> 0 | W39: =V39+T39+P39+K39 -> 0
A40: =A39+1 -> 33 | C40: =IFERROR(VLOOKUP(B40,'Importer Data Fields'!C:D,2,0),"") | I40: lot | K40: =J40*H40 -> 0 | N40: =ROUND(L40*M40*H40,0) -> 0 | P40: =O40*N40 -> 0 | T40: =S40*Q40 -> 0 | V40: =H40*U40 -> 0 | W40: =V40+T40+P40+K40 -> 0
A41: =A40+1 -> 34 | B41: 03 Concrete | K41: =J41*H41 -> 0 | N41: =ROUND(L41*M41*H41,0) -> 0 | P41: =O41*N41 -> 0 | T41: =S41*Q41 -> 0 | V41: =H41*U41 -> 0 | W41: =V41+T41+P41+K41 -> 0 | Y41: =SUM(W41:W52) -> 0
A42: =A41+1 -> 35 | C42: =IFERROR(VLOOKUP(B42,'Importer Data Fields'!C:D,2,0),"") | K42: =J42*H42 -> 0 | N42: =ROUND(L42*M42*H42,0) -> 0 | P42: =O42*N42 -> 0 | T42: =S42*Q42 -> 0 | V42: =H42*U42 -> 0 | W42: =V42+T42+P42+K42 -> 0
...

Sheet Importer Data Fields
A1: Sub Job | B1: Sub Job Description | C1: Cost Code | D1: Cost Code Description | E1: Cost Type | F1: Cost Type Description | G1: BLI UOM | H1: BPQ UOM | I1: BOOLEAN
A2: None | B2: None | C2: None | D2: None | E2: E | F2: Equipment | G2: days | H2: ea | I2: True
C3: 00-000 | D3: Do Not Use | E3: L | F3: Labor | G3: hours | H3: ls | I3: False
C4: 01-3120 | D4: Vice President | E4: M | F4: Material | G4: months | H4: lf
C5: 01-3126 | D5: Pre-construction | E5: None | F5: None | G5: weeks | H5: m
C6: 01-3127 | D6: Sr. Project Manager | E6: R | F6: Contract Revenue | G6: years | H6: mm
C7: 01-3128 | D7: Project Manager | E7: S | F7: Subcontract | G7: ea | H7: m²
C8: 01-3129 | D8: Assistant Project Manager (APM) | E8: X | F8: Expense | G8: ls | H8: sf
C9: 01-3130 | D9: Project Engineer | G9: lf | H9: sy
C10: 01-3131 | D10: Field Engineer | G10: m | H10: cy
C11: 01-3132 | D11: Intern | G11: mm | H11: m³
C12: 01-3142 | D12: General Superintendent | G12: m² | H12: kg
C13: 01-3143 | D13: Sr. Superintendent | G13: sf | H13: lbs
C14: 01-3144 | D14: Superintendent | G14: sy | H14: t
C15: 01-3145 | D15: Assistant Superintendent | G15: cy | H15: ton
C16: 01-3223 | D16: Construction Layout | G16: m³
C17: 01-3236 | D17: Aerial & Periodic Drones | G17: kg
C18: 01-3238 | D18: Jobsite Security | G18: lbs
C19: 01-3245 | D19: Office Supplies | G19: t
C20: 01-3247 | D20: Printing & Copying | G20: ton
C21: 01-3249 | D21: Postage & Courier
C22: 01-3329 | D22: LEED Documentation
C23: 01-3514 | D23: Legal Fees
C24: 01-4123 | D24: Fees
C25: 01-4124 | D25: Sanitary Fees
C26: 01-4126 | D26: Permit Requirements
C27: 01-4523 | D27: Testing and Inspections
C28: 01-4533 | D28: Municipality Inspections
C29: 01-4613 | D29: Winter Conditions
C30: 01-5113 | D30: Temporary Electric
C31: 01-5116 | D31: Temporary Fire Protection
C32: 01-5119 | D32: Temporary Fuel
... C358: 55-0500 | D358: Contractor Fee

Sheet SubList
B1: Company | C1: Previsouly Sent Pricing | D1: Bid Decision | E1: Email Sent? Y/N | F1: Phone Call Follow Up? Y/N | G1: Bid Received? Y/N | H1: Contact | I1: Email | J1: Cell | K1: Price | L1: Comments | M1: Scope Includes? | N1: Scope Includes? | O1: Scope Includes? | P1: Scope Includes? | Q1: Scope Includes? | R1: Scope Includes? | S1: Scope Includes? | T1: Scope Includes? | U1: Scope Includes? | V1: Scope Includes?
B2: 01 General Conditions
A3: 1
A4: 2
A5: 3
A6: 4
A7: 5
B8: 02 Existing Conditions
A9: 1
A10: 2
A11: 3
A12: 4
A13: 5
B14: 03 Concrete | F14: Total Received: | G14: =COUNTIF(G15:G26,"yes") -> 5
A15: 1 | B15: CC Concrete | C15: Yes | D15: Bidding | E15: Yes | F15: No | G15: Yes | H15: C Weber | I15: cweber@ccconcrete.net | J15: 317-450-3317 | K15: 159921 | M15: Concrete
A16: 2 | B16: W.E. Beaty INC | C16: Yes | D16: Bidding | E16: Yes | F16: No | G16: No | H16: Matt Hillen | I16: mhillen@Webeatyinc.com | J16: 317-502-1331 | L16: Estimate to be sent by Wed 22nd | M16: Concrete
A17: 3 | B17: Custom Concrete | C17: No | D17: Bidding | E17: No | F17: Yes (spoke to) | G17: Yes | H17: Bryan Ness | I17: bryann@customconcrete.com | J17: 317-767-1439 | K17: 544500 | L17: Bryan is emailing Andrew questions | M17: Concrete
A18: 4 | B18: Karns INC | C18: Received Drawings but never sent price | D18: Bidding | E18: Yes | F18: Yes (spoke to) | G18: No | H18: Clayton Karns | I18: clay.karns@karnsinc.com | J18: 317-872-2529 | L18: Will have price sent back 1/17 | M18: Concrete
A19: 5 | B19: Trace Construction | C19: No | D19: Undecided | E19: Yes | F19: Yes (spoke to) | G19: No | H19: Caleb Shetterley | I19: cshetterley@traceconstruction.net | J19: 765-617-3534 / 317-362-0119 ext. 2003 | L19: Left voicemail 1/17.Not 100% sure if they will be bidding this project as of 1/8/25, will notifiy on building connected. | M19: Concrete
A20: 6 | B20: CEP Concrete Construction | C20: No | D20: Bidding | E20: No | F20: Yes (spoke to) | G20: Yes | H20: Bill Clemons | I20: bill@cepconcrete.com | J20: 317-534-8595 | K20: 146000 | L20: Received 1/17 | M20: Concrete
A21: 7 | B21: M&C Concrete | C21: No | D21: Bidding | E21: No | F21: Yes (no answer) | G21: No | H21: Tyler Sizelove | I21: tsizelove@mc-concrete.com | J21: 765-661-2482 | L21: Will need until the 20th-21st | M21: Concrete
A22: 8 | B22: Weber Concrete Construction | C22: No | D22: Not Bidding | E22: No | F22: Yes (spoke to) | G22: No | H22: Randy Fuller | I22: randyf@weberconcrete.com | J22: 317-447-2851 | L22: "We are a poured wall contractor" | M22: Concrete
A23: 9 | B23: Torrez Concrete | C23: No | D23: Undecided | E23: No | F23: Yes (no answer) | G23: No | H23: Torrez | I23: godlytorrez@gmail.com | J23: 317-993-8770 | L23: Left voicemail 1/17/2025 | M23: Concrete
A24: 10 | B24: Merrit Contracting INC | C24: No | D24: Bidding | E24: No | F24: Yes (spoke to) | G24: Yes | H24: Brent Wright | I24: bwright@merrittcontracting.com | J24: 317-646-3289 / 765-486-0947 | K24: 127755 | M24: Concrete
A25: 11 | B25: Howard Companies | C25: No | D25: Bidding | E25: Yes | F25: Yes (spoke to) | G25: Yes | H25: Josh Dillon | I25: jdillon@howardcompanies.com | J25: 317-363-5250 | K25: 129358.25 | L25: bid received 1/16
A26: 12 | B26: Allied Concrete Workers Inc | C26: Received Drawings but never sent price | D26: Bidding | E26: Yes | F26: Yes (no answer) | G26: No | H26: Terry Curtis | I26: terry@alliedcwinc.com | L26: Terry will have price sent back today | M26: Concrete
B27: 04 Masonry
A28: 1
A29: 2
A30: 3
A31: 4
A32: 5
B33: 05 Metals
A34: 1
A35: 2
A36: 3
A37: 4
A38: 5
B39: 06 Wood Plastics Composits
A40: 1
...
